<?xml version="1.0" ?>
<robot name="glados" xmlns:xacro="http://www.ros.org/wiki/xacro">
  
  <link name="base_footprint">
    <inertial>
      <origin xyz="0 0 0" rpy="0 0 0"/>
      <mass value="0.0"/>
      <inertia ixx="0.0" ixy="0.0" ixz="0.0" iyy="0.0" iyz="0.0" izz="0.0"/>
    </inertial>
  </link>

  <link name="chassis">
    <inertial>
      <origin xyz="0 0 0.0875" rpy="0 0 0"/>
      <mass value="1.14395"/>
      <inertia ixx="0.126164" ixy="0" ixz="0" iyy="0.416519" iyz="0" izz="0.481014"/>
    </inertial>
    <visual>
      <geometry>
        <box size="0.65 0.245 0.05"/>
      </geometry>
      <material name="blue">
        <color rgba="0.5 0.5 1.0 1"/>
      </material>
    </visual>
    <collision>
      <geometry>
        <box size="0.65 0.245 0.05"/>
      </geometry>
    </collision>
  </link>

  <joint name="base_footprint_to_chassis" type="fixed">
    <parent link="base_footprint"/>
    <child link="chassis"/>
  </joint>

  <link name="front_left_wheel">
    <inertial>
      <origin xyz="0 0 0" rpy="0 0 0"/>
      <mass value="2"/>
      <inertia ixx="0.145833" ixy="0" ixz="0" iyy="0.145833" iyz="0" izz="0.125"/>
    </inertial>
    <visual>
      <origin xyz="0 0 0" rpy="1.5707 0 0"/>
      <geometry>
        <mesh filename="package://glados_description/models/glados/meshes/mecanum_wheel_left.STL" scale="0.002 0.002 0.002"/>
      </geometry>
      <material name="gray">
        <color rgba="0.2 0.2 0.2 1"/>
      </material>
    </visual>
    <collision>
      <geometry>
        <sphere radius="0.1"/>
      </geometry>
    </collision>
  </link>

  <joint name="front_left_wheel_joint" type="continuous">
    <parent link="chassis"/>
    <child link="front_left_wheel"/>
    <axis xyz="0 0 1"/>
  </joint>

  <link name="rear_left_wheel">
    <inertial>
      <origin xyz="0 0 0" rpy="0 0 0"/>
      <mass value="2"/>
      <inertia ixx="0.145833" ixy="0" ixz="0" iyy="0.145833" iyz="0" izz="0.125"/>
    </inertial>
    <visual>
      <origin xyz="0 0 0" rpy="1.5707 0 0"/>
      <geometry>
        <mesh filename="package://glados_description/models/glados/meshes/mecanum_wheel_right.STL" scale="0.002 0.002 0.002"/>
      </geometry>
      <material name="gray">
        <color rgba="0.2 0.2 0.2 1"/>
      </material>
    </visual>
    <collision>
      <geometry>
        <sphere radius="0.1"/>
      </geometry>
    </collision>
  </link>

  <joint name="rear_left_wheel_joint" type="continuous">
    <parent link="chassis"/>
    <child link="rear_left_wheel"/>
    <axis xyz="0 0 1"/>
  </joint>

  <link name="front_right_wheel">
    <inertial>
      <origin xyz="0 0 0" rpy="0 0 0"/>
      <mass value="2"/>
      <inertia ixx="0.145833" ixy="0" ixz="0" iyy="0.145833" iyz="0" izz="0.125"/>
    </inertial>
    <visual>
      <origin xyz="0 0 0" rpy="1.5707 0 0"/>
      <geometry>
        <mesh filename="package://glados_description/models/glados/meshes/mecanum_wheel_right.STL" scale="0.002 0.002 0.002"/>
      </geometry>
      <material name="gray">
        <color rgba="0.2 0.2 0.2 1"/>
      </material>
    </visual>
    <collision>
      <geometry>
        <sphere radius="0.1"/>
      </geometry>
    </collision>
  </link>

  <joint name="front_right_wheel_joint" type="continuous">
    <parent link="chassis"/>
    <child link="front_right_wheel"/>
    <axis xyz="0 0 1"/>
  </joint>

  <link name="rear_right_wheel">
    <inertial>
      <origin xyz="0 0 0" rpy="0 0 0"/>
      <mass value="2"/>
      <inertia ixx="0.145833" ixy="0" ixz="0" iyy="0.145833" iyz="0" izz="0.125"/>
    </inertial>
    <visual>
      <origin xyz="0 0 0" rpy="1.5707 0 0"/>
      <geometry>
        <mesh filename="package://glados_description/models/glados/meshes/mecanum_wheel_left.STL" scale="0.002 0.002 0.002"/>
      </geometry>
      <material name="gray">
        <color rgba="0.2 0.2 0.2 1"/>
      </material>
    </visual>
    <collision>
      <geometry>
        <sphere radius="0.1"/>
      </geometry>
    </collision>
  </link>

  <joint name="rear_right_wheel_joint" type="continuous">
    <parent link="chassis"/>
    <child link="rear_right_wheel"/>
    <axis xyz="0 0 1"/>
  </joint>

  <link name="lidar_link">
    <inertial>
      <origin xyz="0.325 0 0.045" rpy="0 0 0"/>
      <mass value="0.1"/>
      <inertia ixx="0.000166667" ixy="0.0" ixz="0.0" iyy="0.000166667" iyz="0.0" izz="0.000166667"/>
    </inertial>
    <visual>
      <geometry>
        <cylinder length="0.04" radius="0.04"/>
      </geometry>
    </visual>
    <collision>
      <geometry>
        <cylinder length="0.04" radius="0.04"/>
      </geometry>
    </collision>
  </link>

  <joint name="lidar_joint" type="fixed">
    <parent link="chassis"/>
    <child link="lidar_link"/>
  </joint>

</robot>