<?xml version="1.0" ?>
<sdf version="1.6">
    <model name='glados' xmlns:gz="http://gazebosim.org/schema">
      
      <!-- <link name="base_link">
      </link>

      <joint name="base_footprint_joint" type="fixed">
        <parent>base_link</parent>
        <child>base_footprint</child>
        <origin xyz="0 0 0" rpy="0 0 0"/>
      </joint>
      -->
      <link name='base_footprint'>
        <pose>0 0 0 0 0 0</pose>
      </link>

      <joint name='base_footprint_to_chassis' type='fixed'>
        <parent>base_footprint</parent>
        <child>chassis</child>
      </joint>

      <link name='chassis'>
        <pose>0 0 0.0875 0 0 0</pose>
        <inertial>
          <mass>1.14395</mass>
          <inertia>
            <ixx>0.126164</ixx>
            <ixy>0</ixy>
            <ixz>0</ixz>
            <iyy>0.416519</iyy>
            <iyz>0</iyz>
            <izz>0.481014</izz>
          </inertia>
        </inertial>
        <visual name='visual'>
          <geometry>
            <box>
              <size>0.65 0.245 0.05</size>
            </box>
          </geometry>
          <material>
            <ambient>0.5 0.5 1.0 1</ambient>
            <diffuse>0.5 0.5 1.0 1</diffuse>
            <specular>0.0 0.0 1.0 1</specular>
          </material>
        </visual>
        <collision name='collision'>
          <geometry>
            <box>
              <size>0.65 0.245 0.05</size>
            </box>
          </geometry>
        </collision>
      </link>

      <link name='front_left_wheel'>
        <pose relative_to="chassis">0.2 0.1625 0 -1.5707 0 0</pose>
        <inertial>
          <mass>2</mass>
          <inertia>
            <ixx>0.145833</ixx>
            <ixy>0</ixy>
            <ixz>0</ixz>
            <iyy>0.145833</iyy>
            <iyz>0</iyz>
            <izz>0.125</izz>
          </inertia>
        </inertial>
        <visual name='visual'>
          <pose>0 0 0 1.5707 0 0</pose>
          <geometry>
            <mesh>
              <uri>package://glados_description/models/glados/meshes/mecanum_wheel_left.STL</uri>
              <scale>0.002 0.002 0.002</scale>
            </mesh>
          </geometry>
          <material>
            <ambient>0.2 0.2 0.2 1</ambient>
            <diffuse>0.2 0.2 0.2 1</diffuse>
            <specular>0.2 0.2 0.2 1</specular>
          </material>
        </visual>
        <collision name='collision'>
          <geometry>
            <sphere>
              <radius>0.1</radius>
            </sphere>
          </geometry>
          <surface>
            <friction>
              <ode>
                <mu>1.0</mu>
                <mu2>0.0</mu2>
                <fdir1 gz:expressed_in="chassis">1 -1 0</fdir1>
              </ode>
            </friction>
          </surface>
        </collision>
      </link>

      <link name='rear_left_wheel'>
        <pose relative_to="chassis">-0.2 0.1625 0 -1.5707 0 0</pose>
        <inertial>
          <mass>2</mass>
          <inertia>
            <ixx>0.145833</ixx>
            <ixy>0</ixy>
            <ixz>0</ixz>
            <iyy>0.145833</iyy>
            <iyz>0</iyz>
            <izz>0.125</izz>
          </inertia>
        </inertial>
        <visual name='visual'>
          <pose>0 0 0 1.5707 0 0</pose>
          <geometry>
            <mesh>
              <uri>package://glados_description/models/glados/meshes/mecanum_wheel_right.STL</uri>
              <scale>0.002 0.002 0.002</scale>
            </mesh>
          </geometry>
          <material>
            <ambient>0.2 0.2 0.2 1</ambient>
            <diffuse>0.2 0.2 0.2 1</diffuse>
            <specular>0.2 0.2 0.2 1</specular>
          </material>
        </visual>
        <collision name='collision'>
          <geometry>
            <sphere>
              <radius>0.1</radius>
            </sphere>
          </geometry>
          <surface>
            <friction>
              <ode>
                <mu>1.0</mu>
                <mu2>0.0</mu2>
                <fdir1 gz:expressed_in="chassis">1 1 0</fdir1>
              </ode>
            </friction>
          </surface>
        </collision>
      </link>

      <link name='front_right_wheel'>
        <pose relative_to="chassis">0.2 -0.1625 0 -1.5707 0 0</pose>
        <inertial>
          <mass>2</mass>
          <inertia>
            <ixx>0.145833</ixx>
            <ixy>0</ixy>
            <ixz>0</ixz>
            <iyy>0.145833</iyy>
            <iyz>0</iyz>
            <izz>0.125</izz>
          </inertia>
        </inertial>
        <visual name='visual'>
          <pose>0 0 0 1.5707 0 0</pose>
          <geometry>
            <mesh>
              <uri>package://glados_description/models/glados/meshes/mecanum_wheel_right.STL</uri>
              <scale>0.002 0.002 0.002</scale>
            </mesh>
          </geometry>
          <material>
            <ambient>0.2 0.2 0.2 1</ambient>
            <diffuse>0.2 0.2 0.2 1</diffuse>
            <specular>0.2 0.2 0.2 1</specular>
          </material>
        </visual>
        <collision name='collision'>
          <geometry>
            <sphere>
              <radius>0.1</radius>
            </sphere>
          </geometry>
          <surface>
            <friction>
              <ode>
                <mu>1.0</mu>
                <mu2>0.0</mu2>
                <fdir1 gz:expressed_in="chassis">1 1 0</fdir1>
              </ode>
            </friction>
          </surface>
        </collision>
      </link>

      <link name='rear_right_wheel'>
        <pose relative_to="chassis">-0.2 -0.1625 0 -1.5707 0 0</pose>
        <inertial>
          <mass>2</mass>
          <inertia>
            <ixx>0.145833</ixx>
            <ixy>0</ixy>
            <ixz>0</ixz>
            <iyy>0.145833</iyy>
            <iyz>0</iyz>
            <izz>0.125</izz>
          </inertia>
        </inertial>
        <visual name='visual'>
          <pose>0 0 0 1.5707 0 0</pose>
          <geometry>
            <mesh>
              <uri>package://glados_description/models/glados/meshes/mecanum_wheel_left.STL</uri>
              <scale>0.002 0.002 0.002</scale>
            </mesh>
          </geometry>
          <material>
            <ambient>0.2 0.2 0.2 1</ambient>
            <diffuse>0.2 0.2 0.2 1</diffuse>
            <specular>0.2 0.2 0.2 1</specular>
          </material>
        </visual>
        <collision name='collision'>
          <geometry>
            <sphere>
              <radius>0.1</radius>
            </sphere>
          </geometry>
          <surface>
            <friction>
              <ode>
                <mu>1.0</mu>
                <mu2>0.0</mu2>
                <fdir1 gz:expressed_in="chassis">1 -1 0</fdir1>
              </ode>
            </friction>
          </surface>
        </collision>
      </link>

      <joint name='front_left_wheel_joint' type='revolute'>
        <parent>chassis</parent>
        <child>front_left_wheel</child>
        <axis>
          <xyz>0 0 1</xyz>
          <limit>
            <lower>-1.79769e+308</lower>
            <upper>1.79769e+308</upper>
          </limit>
        </axis>
      </joint>

      <joint name='front_right_wheel_joint' type='revolute'>
        <parent>chassis</parent>
        <child>front_right_wheel</child>
        <axis>
          <xyz>0 0 1</xyz>
          <limit>
            <lower>-1.79769e+308</lower>
            <upper>1.79769e+308</upper>
          </limit>
        </axis>
      </joint>

      <joint name='rear_left_wheel_joint' type='revolute'>
        <parent>chassis</parent>
        <child>rear_left_wheel</child>
        <axis>
          <xyz>0 0 1</xyz>
          <limit>
            <lower>-1.79769e+308</lower>
            <upper>1.79769e+308</upper>
          </limit>
        </axis>
      </joint>

      <joint name='rear_right_wheel_joint' type='revolute'>
        <parent>chassis</parent>
        <child>rear_right_wheel</child>
        <axis>
          <xyz>0 0 1</xyz>
          <limit>
            <lower>-1.79769e+308</lower>
            <upper>1.79769e+308</upper>
          </limit>
        </axis>
      </joint>

      <link name="lidar_link">
        <pose relative_to="chassis">0.325 0 0.045 0 0 0</pose>
        <inertial>
          <mass>0.1</mass>
          <inertia>
            <ixx>0.000166667</ixx>
            <iyy>0.000166667</iyy>
            <izz>0.000166667</izz>
          </inertia>
        </inertial>
        <collision name="collision">
          <geometry>
            <cylinder>
              <radius>0.04</radius>
              <length>0.04</length>
            </cylinder>
          </geometry>
        </collision>
        <visual name="visual">
          <geometry>
            <cylinder>
              <radius>0.04</radius>
              <length>0.04</length>
            </cylinder>
          </geometry>
        </visual>
        <sensor name='gpu_lidar' type='gpu_lidar'>
          <pose>0 0 0 0 0 0</pose>
          <topic>scan</topic>
          <gz_frame_id>lidar_link</gz_frame_id>
          <update_rate>10</update_rate>
          <lidar>
            <scan>
              <horizontal>
                <samples>640</samples>
                <resolution>1</resolution>
                <min_angle>-1.396263</min_angle>
                <max_angle>1.396263</max_angle>
              </horizontal>
              <vertical>
                <samples>1</samples>
                <resolution>1</resolution>
                <min_angle>0.0</min_angle>
                <max_angle>0.0</max_angle>
              </vertical>
            </scan>
            <range>
              <min>0.08</min>
              <max>10.0</max>
              <resolution>0.01</resolution>
            </range>
          </lidar>
          <visualize>true</visualize>
        </sensor>
      </link>

      <joint name='lidar_joint' type='fixed'>
        <parent>chassis</parent>
        <child>lidar_link</child>
      </joint>
    
      <link name="camera_link">
        <pose relative_to="chassis">0.330 0 -0.0125 0 0 0</pose>
        <inertial>
          <mass>0.1</mass>
          <inertia>
            <ixx>0.000166667</ixx>
            <iyy>0.000166667</iyy>
            <izz>0.000166667</izz>
          </inertia>
        </inertial>
        <collision name="collision">
          <geometry>
            <box>
              <size>0.01 0.1 0.025</size>
            </box>
          </geometry>
        </collision>
        <!-- <visual name="visual">
          <box>
            <size>0.01 0.1 0.025</size>
          </box>
        </visual> -->
        <visual name= "visual">
          <pose>-0.01 0 0 0 0 1.5707</pose>
          <geometry>
            <mesh>
              <uri>package://glados_description/models/glados/meshes/realsense.dae</uri>
              <submesh>
                <name>RealSense</name>
                <center>false</center>
              </submesh>
            </mesh>
          </geometry>
          <material>
            <diffuse>1.0 1.0 1.0</diffuse>
            <specular>1.0 1.0 1.0</specular>
            <pbr>
              <metal>
                <albedo_map>package://glados_description/models/glados/materials/textures/RealSense_Albedo.png</albedo_map>
                <normal_map>package://glados_description/models/glados/materials/textures/RealSense_Normal.png</normal_map>
                <metalness_map>package://glados_description/models/glados/materials/textures/RealSense_Metalness.png</metalness_map>
                <roughness_map>package://glados_description/models/glados/materials/textures/RealSense_Roughness.png</roughness_map>
              </metal>
            </pbr>
            <!-- fallback to script if no PBR support-->
            <script>
              <uri>package://glados_description/models/glados/materials/scripts/</uri>
              <uri>package://glados_description/models/glados/materials/textures/</uri>
              <name>UrbanTile/RealSense_Diffuse</name>
            </script>
          </material>
        </visual>
        <sensor name="camera" type="rgbd_camera">
          <update_rate>10</update_rate>
          <topic>camera</topic>
          <camera>
            <horizontal_fov>1.05</horizontal_fov>
            <image>
              <width>256</width>
              <height>256</height>
            </image>
            <clip>
              <near>0.1</near>
              <far>10.0</far>
            </clip>
          </camera>
        </sensor>
      </link>

      <joint name='camera_joint' type='fixed'>
        <parent>chassis</parent>
        <child>camera_link</child>
      </joint>

      <!-- <link name="camera_optical_link">
        <pose relative_to="camera_link">0 0 0 -1.5707 0 -1.5707</pose>
      </link>

      <joint name='camera_optical_joint' type='fixed'>
        <parent>camera_link</parent>
        <child>camera_optical_link</child>
      </joint> -->

      <plugin
        filename="gz-sim-mecanum-drive-system"
        name="gz::sim::systems::MecanumDrive">
        <front_left_joint>front_left_wheel_joint</front_left_joint>
        <front_right_joint>front_right_wheel_joint</front_right_joint>
        <back_left_joint>rear_left_wheel_joint</back_left_joint>
        <back_right_joint>rear_right_wheel_joint</back_right_joint>
        <wheel_separation>0.245</wheel_separation>
        <wheelbase>0.4</wheelbase>
        <wheel_radius>0.1</wheel_radius>
        <min_acceleration>-5</min_acceleration>
        <max_acceleration>5</max_acceleration>
      </plugin>

    </model>
</sdf>